# 错误传递与处理

> 在执行JavaScript代码的时候，有些情况下会发生错误。
> 错误分两种，一种是程序写的逻辑不对，导致代码执行异常。例如：
>
> ```javascript
> const s = null
> const len = s.length // TypeError：null变量没有length属性
> ```
>
> 对于这种错误，要修复程序。
> 一种是执行过程中，程序可能遇到无法预测的异常情况而报错，例如，网络连接中断，读取不存在的文件，没有操作权限等。
> 对于这种错误，我们需要处理它，并可能需要给用户反馈。

## 一、错误处理

**try...catch...finally**

使用try ... catch ... finally处理错误时，我们编写的代码如下：

```javascript
'use strict'
let r1; let r2
const s = null
try {
  r1 = s.length // 此处应产生错误
  r2 = 100 // 该语句不会执行
}
catch (e) {
  console.log(`出错了：${e}`)
}
finally {
  console.log('finally')
}
console.log(`r1 = ${r1}`) // r1应为undefined
console.log(`r2 = ${r2}`) // r2应为undefined
// log顺序：
// 出错了：TypeError: Cannot read properties of null (reading 'length')
// finally
// r1 = undefined
// r2 = undefined
```

### 1、错误类型

> JavaScript有一个标准的[Error](https://developer.mozilla.org/zh-CN/docs/Web/JavaScript/Reference/Global_Objects/Error)对象表示错误，当运行时错误产生时，Error 对象会被抛出。还有从Error派生的TypeError、RangeError等错误对象。

我们在处理错误时，可以通过catch(e)捕获的变量e访问错误对象：

```text
interface Error {
    /** 错误名称 由构造函数决定的 */
    name: string;
    /** 错误消息 由Error构造函数的第一个参数提供的字符串 */
    message: string;
    /** 一个非标准的属性，用于堆栈跟踪。 */
    stack?: string;
}

try {
    ...
} catch (e: Error) {
    if (e instanceof TypeError) {
        console.error('Type error!');
    } else if (e instanceof Error) {
        console.error(e.message);
    } else {
        console.error('Error: ' + e);
    }
}
```

### 2、错误抛出

**throw**

> 除了代码执行时发生的错误，还可以使用throw主动抛出错误，让执行流程直接跳转到catch块

例如，下面的代码让用户输入一个数字，程序接收到的实际上是一个字符串，然后用parseInt()转换为整数。当用户输入不合法的时候，我们就抛出错误：

```javascript
'use strict'
let r, n, s
try {
  s = prompt('请输入一个数字')
  n = Number.parseInt(s)
  if (Number.isNaN(n)) {
    throw new TypeError('输入错误')
  }
  // 计算平方:
  r = n * n
  console.log(`${n} * ${n} = ${r}`)
}
catch (e) {
  console.log(`出错了：${e}`)
}
```

实际上，JavaScript允许抛出任意对象，包括数字、字符串。但是，**`最好还是抛出一个Error对象`**。
最后，**当我们用catch捕获错误时，一定要编写错误处理语句：**

::: danger

```javascript
let n = 0; let s
try {
  n = s.length
}
catch (e) {
}
console.log(n)
```

:::

**哪怕仅仅把错误打印出来，也不要什么也不干：**

```javascript
let n = 0; let s
try {
  n = s.length
}
catch (e) {
  console.log(e) // [!code ++]
}
console.log(n)
```

**因为catch到错误却什么都不执行，就不知道程序执行过程中到底有没有发生错误。**

## 二、错误传播

如果代码发生了错误，又没有被try ... catch捕获，那么，程序执行流程会跳转到哪呢？

```javascript
function getLength(s) {
  return s.length
}

function printLength() {
  console.log(getLength('abc')) // 3
  console.log(getLength(null)) // Error!
}

printLength()
```

如果在一个函数内部发生了错误，它自身没有捕获，错误就会被抛到外层调用函数，如果外层函数也没有捕获，该错误会一直沿着函数调用链向上抛出，直到被JavaScript引擎捕获，代码终止执行。

所以，**我们不必在每一个函数内部捕获错误，只需要在合适的地方来个统一捕获**，一网打尽：

```javascript
function main(s) {
  console.log('BEGIN main()')
  try {
    foo(s)
  }
  catch (e) {
    console.log(`出错了：${e}`)
  }
  console.log('END main()')
}

function foo(s) {
  console.log('BEGIN foo()')
  bar(s)
  console.log('END foo()')
}

function bar(s) {
  console.log('BEGIN bar()')
  console.log(`length = ${s.length}`)
  console.log('END bar()')
}

main(null)
```

**使用catch捕获的错误将不会继续向外抛出**。比如：

```javascript
function a() {
  return new Promise((resolve, reject) => {
    reject(new Error(err))
  })
}
try {
  a().catch((err) => {
    console.log('promise>>>', err)
  })
}
catch (error) {
  console.log('window>>>', error)
}

// 结果：
// promise ReferenceError: err is not defined
```
